<?xml version='1.0'?>
<sdf version='1.4'>
  <model name="my_robot">
	<link name='chassis'>
            <pose>0 0 .2 0 0 0</pose>
	    <inertial>
		 <mass>10.0</mass>
		 <pose>0.0 0 0.1 0 0 0</pose>
		 <inertia>
		 <ixx>0.5</ixx>
		 <iyy>1.0</iyy>
		 <izz>0.1</izz>
		 </inertia>
	    </inertial>
            <collision name='collision'>
            <geometry>
              <cylinder>
	      <radius>.15</radius>
	      <length>.3</length>
	    </cylinder>
            </geometry>
          </collision>

            <visual name='visual'>
              <geometry>
              <cylinder>
	      <radius>.15</radius>
	      <length>.3</length>
	    </cylinder>
            </geometry>
            </visual>

	 <collision name='caster_collision'>
            <pose>-0.08 0 -0.15 0 0 0</pose>
            <geometry>
                <sphere>
                <radius>.05</radius>
              </sphere>
            </geometry>

            <surface>
              <friction>
                <ode>
                  <mu>0</mu>
                  <mu2>0</mu2>
                  <slip1>1.0</slip1>
                  <slip2>1.0</slip2>
                </ode>
              </friction>
            </surface>
          </collision>

          <visual name='caster_visual'>
            <pose>-0.08 0 -0.15 0 0 0</pose>
            <geometry>
              <sphere>
                <radius>.05</radius>
              </sphere>
            </geometry>
          </visual>
		
	  <sensor name="ir0" type="ray">
		<pose>0.17 0 0.0 0 0 0</pose>
		<ray>
		  <scan>
		    <horizontal>
		      <samples>1</samples>
		      <resolution>1</resolution>
		      <min_angle>-0.0001</min_angle>
		      <max_angle>0.0001</max_angle>
		    </horizontal>
		  </scan>
		  <range>
		    <min>0.08</min>
		    <max>.8</max>
		    <resolution>0.01</resolution>
		  </range>
		  <noise>
		    <type>gaussian</type>
		    <mean>0.0</mean>
		    <stddev>0.01</stddev>
		  </noise>
		</ray>
		<plugin name="gazebo_ros_head_hokuyo_controller" filename="libgazebo_ros_laser.so">
			<topicName>/ir0</topicName>
			<frameName>base</frameName>
	      	</plugin>
		
		<always_on>1</always_on>
		<update_rate>10</update_rate>
		<visualize>true</visualize>
	      </sensor>
	
	
          </link>

	<link name="left_wheel">
		<pose>0.06 0.17 0.065 0 1.5707 1.5707</pose>
		<collision name="collision">
		  <geometry>
		    <cylinder>
		      <radius>.065</radius>
		      <length>.02</length>
		    </cylinder>
		  </geometry>
		</collision>
		<visual name="visual">
		  <geometry>
		    <cylinder>
		      <radius>.065</radius>
		      <length>.02</length>
		    </cylinder>
		  </geometry>
		</visual>
      </link>
      <link name="right_wheel">
        <pose>0.06 -0.17 0.065 0 1.5707 1.5707</pose>
        <collision name="collision">
          <geometry>
            <cylinder>
              <radius>.065</radius>
              <length>.02</length>
            </cylinder>
          </geometry>
        </collision>
        <visual name="visual">
          <geometry>
            <cylinder>
              <radius>.065</radius>
              <length>.02</length>
            </cylinder>
          </geometry>
        </visual>
      </link>

 <joint type="revolute" name="left_wheel_hinge">
        <pose>0 0 -0.03 0 0 0</pose>
        <child>left_wheel</child>
        <parent>chassis</parent>
        <axis>
          <xyz>0 1 0</xyz>
        </axis>
      </joint>

      <joint type="revolute" name="right_wheel_hinge">
        <pose>0 0 0.03 0 0 0</pose>
        <child>right_wheel</child>
        <parent>chassis</parent>
        <axis>
          <xyz>0 1 0</xyz>
        </axis>
      </joint>

	<!--<plugin name="differential_drive_controller" filename="libgazebo_ros_diff_drive.so">
	 <alwaysOn>true</alwaysOn>
	 <updateRate>20</updateRate>
	 <leftJoint>left_wheel_hinge</leftJoint>
	 <rightJoint>right_wheel_hinge</rightJoint>
	 <wheelSeparation>0.26</wheelSeparation>
	 <wheelDiameter>0.2</wheelDiameter>
	 <torque>20</torque>
	 <commandTopic>cmd_vel</commandTopic>
	 <odometryTopic>odom</odometryTopic>
	 <odometryFrame>odom</odometryFrame>
	 <robotBaseFrame>base_footprint</robotBaseFrame>
	<legacyMode>true</legacyMode>
	 </plugin>
-->
  </model>
</sdf>
